2024-05-23 23:49:19,238 FILE: __init__.py IN: infinity_polling MESSAGE: Infinity polling exception: HTTPSConnectionPool(host='api.telegram.org', port=443): Max retries exceeded with url: /bot7001432483:***********************************/getMe (Caused by NewConnectionError('<urllib3.connection.HTTPSConnection object at 0x0000018AF3D2FC90>: Failed to establish a new connection: [WinError 10051] Сделана попытка выполнить операцию на сокете при отключенной сети'))
2024-05-23 23:49:20,035 FILE: __init__.py IN: infinity_polling MESSAGE: Exception traceback:
Traceback (most recent call last):
  File "C:\Users\olegb\PycharmProjects\pythonProject52\venv\Lib\site-packages\urllib3\connection.py", line 198, in _new_conn
    sock = connection.create_connection(
           ^^^^^^^^^^^^^^^^^^^^^^^^^^^^^
  File "C:\Users\olegb\PycharmProjects\pythonProject52\venv\Lib\site-packages\urllib3\util\connection.py", line 85, in create_connection
    raise err
  File "C:\Users\olegb\PycharmProjects\pythonProject52\venv\Lib\site-packages\urllib3\util\connection.py", line 73, in create_connection
    sock.connect(sa)
OSError: [WinError 10051] Сделана попытка выполнить операцию на сокете при отключенной сети

The above exception was the direct cause of the following exception:

Traceback (most recent call last):
  File "C:\Users\olegb\PycharmProjects\pythonProject52\venv\Lib\site-packages\urllib3\connectionpool.py", line 793, in urlopen
    response = self._make_request(
               ^^^^^^^^^^^^^^^^^^^
  File "C:\Users\olegb\PycharmProjects\pythonProject52\venv\Lib\site-packages\urllib3\connectionpool.py", line 491, in _make_request
    raise new_e
  File "C:\Users\olegb\PycharmProjects\pythonProject52\venv\Lib\site-packages\urllib3\connectionpool.py", line 467, in _make_request
    self._validate_conn(conn)
  File "C:\Users\olegb\PycharmProjects\pythonProject52\venv\Lib\site-packages\urllib3\connectionpool.py", line 1099, in _validate_conn
    conn.connect()
  File "C:\Users\olegb\PycharmProjects\pythonProject52\venv\Lib\site-packages\urllib3\connection.py", line 616, in connect
    self.sock = sock = self._new_conn()
                       ^^^^^^^^^^^^^^^^
  File "C:\Users\olegb\PycharmProjects\pythonProject52\venv\Lib\site-packages\urllib3\connection.py", line 213, in _new_conn
    raise NewConnectionError(
urllib3.exceptions.NewConnectionError: <urllib3.connection.HTTPSConnection object at 0x0000018AF3D2FC90>: Failed to establish a new connection: [WinError 10051] Сделана попытка выполнить операцию на сокете при отключенной сети

The above exception was the direct cause of the following exception:

Traceback (most recent call last):
  File "C:\Users\olegb\PycharmProjects\pythonProject52\venv\Lib\site-packages\requests\adapters.py", line 564, in send
    resp = conn.urlopen(
           ^^^^^^^^^^^^^
  File "C:\Users\olegb\PycharmProjects\pythonProject52\venv\Lib\site-packages\urllib3\connectionpool.py", line 847, in urlopen
    retries = retries.increment(
              ^^^^^^^^^^^^^^^^^^
  File "C:\Users\olegb\PycharmProjects\pythonProject52\venv\Lib\site-packages\urllib3\util\retry.py", line 515, in increment
    raise MaxRetryError(_pool, url, reason) from reason  # type: ignore[arg-type]
    ^^^^^^^^^^^^^^^^^^^^^^^^^^^^^^^^^^^^^^^^^^^^^^^^^^^
urllib3.exceptions.MaxRetryError: HTTPSConnectionPool(host='api.telegram.org', port=443): Max retries exceeded with url: /bot7001432483:***********************************/getMe (Caused by NewConnectionError('<urllib3.connection.HTTPSConnection object at 0x0000018AF3D2FC90>: Failed to establish a new connection: [WinError 10051] Сделана попытка выполнить операцию на сокете при отключенной сети'))

During handling of the above exception, another exception occurred:

Traceback (most recent call last):
  File "C:\Users\olegb\PycharmProjects\pythonProject52\venv\Lib\site-packages\telebot\__init__.py", line 1090, in infinity_polling
    self.polling(non_stop=True, timeout=timeout, long_polling_timeout=long_polling_timeout,
  File "C:\Users\olegb\PycharmProjects\pythonProject52\venv\Lib\site-packages\telebot\__init__.py", line 1175, in polling
    logger.info('Starting your bot with username: [@%s]', self.user.username)
                                                          ^^^^^^^^^
  File "C:\Users\olegb\PycharmProjects\pythonProject52\venv\Lib\site-packages\telebot\__init__.py", line 294, in user
    self._user = self.get_me()
                 ^^^^^^^^^^^^^
  File "C:\Users\olegb\PycharmProjects\pythonProject52\venv\Lib\site-packages\telebot\__init__.py", line 1362, in get_me
    apihelper.get_me(self.token)
  File "C:\Users\olegb\PycharmProjects\pythonProject52\venv\Lib\site-packages\telebot\apihelper.py", line 202, in get_me
    return _make_request(token, method_url)
           ^^^^^^^^^^^^^^^^^^^^^^^^^^^^^^^^
  File "C:\Users\olegb\PycharmProjects\pythonProject52\venv\Lib\site-packages\telebot\apihelper.py", line 162, in _make_request
    result = _get_req_session().request(
             ^^^^^^^^^^^^^^^^^^^^^^^^^^^
  File "C:\Users\olegb\PycharmProjects\pythonProject52\venv\Lib\site-packages\requests\sessions.py", line 589, in request
    resp = self.send(prep, **send_kwargs)
           ^^^^^^^^^^^^^^^^^^^^^^^^^^^^^^
  File "C:\Users\olegb\PycharmProjects\pythonProject52\venv\Lib\site-packages\requests\sessions.py", line 703, in send
    r = adapter.send(request, **kwargs)
        ^^^^^^^^^^^^^^^^^^^^^^^^^^^^^^^
  File "C:\Users\olegb\PycharmProjects\pythonProject52\venv\Lib\site-packages\requests\adapters.py", line 597, in send
    raise ConnectionError(e, request=request)
requests.exceptions.ConnectionError: HTTPSConnectionPool(host='api.telegram.org', port=443): Max retries exceeded with url: /bot7001432483:***********************************/getMe (Caused by NewConnectionError('<urllib3.connection.HTTPSConnection object at 0x0000018AF3D2FC90>: Failed to establish a new connection: [WinError 10051] Сделана попытка выполнить операцию на сокете при отключенной сети'))

